Workbook
Name MonthlyChart_Data1: OFFSET('[1]Planned expenses'!$C$37,0,0,1,'Income&expenses'!MonthsWithActual)
Name MonthlyChart_Data1: OFFSET(Expenses!$C$60,0,0,1,MonthsWithActual)
Name MonthsWithActual: COUNTIF('Income&expenses'!$C$37:$N$37,"<>"&0)
Name MonthsWithActual: COUNTIF(#REF!,"<>"&0)

Sheet Expenses 2025
B1: Hotel Yuli EXPENSES
B2: 2025
C6: January | D6: February | E6: March | F6: April | G6: May | H6: June | I6: July | J6: August | K6: September | L6: October | M6: November | N6: December | O6: Total
B8: EMPLOYEE COSTS | C8: JANUARY | D8: FEBRUARY | E8: MARCH | F8: APRIL | G8: MAY | H8: JUNE | I8: JULY | J8: AUGUST | K8: SEPTEMBER | L8: OCTOBER | M8: NOVEMBER | N8: DECEMBER | O8: TOTAL
B9: PLANILLA | C9: =2875875.65/507 -> 5672.3386 | D9: 5680.22 | E9: 5659.75 | F9: 5607.49 | G9: 5779.76 | H9: 5613.73 | I9: 4929.44 | J9: 5221.36 | K9: 5066.78 | L9: 4978.62 | M9: 5066.78 | N9: 10206 | O9: =SUM('Expenses 2025'!$C9:$N9) -> 69482.269
B10: CCSS | C10: =1151457/507 -> 2271.1183 | D10: 2265.64 | E10: 2200.7 | F10: 2172.4 | G10: 2298.15 | H10: 2249.65 | I10: 2090.6 | J10: 2282.25 | K10: 2248 | L10: 2178.81 | M10: 2398 | N10: 2160 | O10: =SUM('Expenses 2025'!$C10:$N10) -> 26815.318
M11: 1500 | N11: 1695 | O11: =SUM('Expenses 2025'!$C11:$N11) -> 3195
B12: TOTAL | C12: =SUM(C9,C10) -> 7943.4569 | D12: =SUM(D9,D10) -> 7945.86 | E12: =SUM(E9,E10) -> 7860.45 | F12: =SUM(F9,F10) -> 7779.89 | G12: =SUM(G9,G10) -> 8077.91 | H12: =SUM(H9,H10) -> 7863.38 | I12: =SUM(I9,I10) -> 7020.04 | J12: =SUM(J9,J10) -> 7503.61 | ... L12: =SUM(L9,L10) -> 7157.43 | M12: =SUM(M9,M10,M11) -> 8964.78 | N12: =SUM(N9:N11) -> 14061 | O12: =SUM(C12:N12) -> 99492.587
B13: Fixed operating expenses | C13: JANUARY | D13: FEBRUARY | E13: MARCH | F13: APRIL | G13: MAY | H13: JUNE | I13: JULY | J13: AUGUST | K13: SEPTEMBER | L13: OCTOBER | M13: NOVEMBER | N13: DECEMBER | O13: TOTAL
B14: Accountant | C14: 715 | D14: 777 | E14: 345.09 | F14: 222.66 | G14: 223.66 | H14: 223.66 | I14: 223.66 | J14: 381.44 | K14: 223 | L14: 223 | M14: 223 | N14: 707 | O14: =SUM('Expenses 2025'!$C14:$N14) -> 4488.17
B15: MANTENIMIENTO DE PISCINAS | C15: =259040/507 -> 510.92702 | D15: 311 | E15: 257.8 | F15: 433.92 | G15: 261.74 | H15: 244.56 | I15: 242.51 | J15: 249.5 | K15: 332 | L15: 320 | M15: 332 | N15: 250 | O15: =SUM('Expenses 2025'!$C15:$N15) -> 3745.957
B16: Gas | C16: 200 | D16: 200 | E16: 200 | F16: 200 | G16: 200 | H16: 200 | I16: 200 | J16: 200 | K16: 200 | L16: 200 | M16: 200 | N16: 103 | O16: =SUM('Expenses 2025'!$C16:$N16) -> 2303
B17: GARDEN/ | C17: 200 | D17: 200 | E17: 200 | F17: 1682 | G17: 200 | H17: 200 | I17: 200 | J17: 200 | K17: 200 | L17: 200 | O17: =SUM('Expenses 2025'!$C17:$N17) -> 3482
B18: Electric | C18: 2355 | D18: 2371 | E18: 2353 | F18: 2471 | G18: 2077 | H18: 2055 | I18: 2103 | J18: 2563 | K18: 2226 | L18: 1911 | M18: 2300 | N18: 2016 | O18: =SUM('Expenses 2025'!$C18:$N18) -> 26801
B19: Water | C19: 193 | D19: 267.83828 | E19: 6.87 | F19: 6.24 | G19: 610.81 | H19: 791.11 | I19: 830.55 | J19: 963.53 | K19: 786.33 | L19: 725.35 | M19: 430 | N19: 466 | O19: =SUM('Expenses 2025'!$C19:$N19) -> 6077.6283
B20: INTERNET | C20: 86.73 | D20: 86.73 | E20: 86.73 | F20: 86.73 | G20: 86.73 | H20: 86.73 | I20: 86.73 | J20: 86.73 | K20: 86.73 | L20: 86.73 | M20: 86.73 | N20: 86.73 | O20: =SUM('Expenses 2025'!$C20:$N20) -> 1040.76
B21: TELEPHONE | C21: 30 | D21: 30 | E21: 30 | F21: 30 | G21: 30 | H21: 30 | I21: 30 | J21: 30 | K21: 30 | L21: 30 | M21: 30 | N21: 30 | O21: =SUM('Expenses 2025'!$C21:$N21) -> 360
B22: Strauss Water | C22: =14771.75/507 -> 29.135602 | D22: =14771.75/507 -> 29.135602 | E22: =14771.75/507 -> 29.135602 | F22: =14771.75/507 -> 29.135602 | G22: =14771.75/507 -> 29.135602 | H22: =14771.75/507 -> 29.135602 | I22: =14771.75/507 -> 29.135602 | J22: =14771.75/507 -> 29.135602 | ... M22: =14771.75/507 -> 29.135602 | N22: 29.14 | O22: =SUM('Expenses 2025'!$C22:$N22) -> 349.63162
B23: SERVICIOS SANITARIOS JS | D23: 964 | G23: 2000 | I23: 628 | L23: 1000 | M23: 500 | N23: 1000 | O23: =SUM('Expenses 2025'!$C23:$N23) -> 6092
B24: GOOGLE LLC | C24: =30639/507 -> 60.431953 | D24: =30639/507 -> 60.431953 | E24: =30639/507 -> 60.431953 | F24: =30639/507 -> 60.431953 | G24: =30639/507 -> 60.431953 | H24: =30639/507 -> 60.431953 | I24: =30639/507 -> 60.431953 | J24: =30639/507 -> 60.431953 | ... M24: =30639/507 -> 60.431953 | N24: 60.43 | O24: =SUM('Expenses 2025'!$C24:$N24) -> 725.18148
B25: MNK Seguros | C25: 230.31 | D25: 230.31 | E25: 230.31 | F25: 230.31 | G25: 230.31 | H25: 297 | I25: 297 | J25: 297 | K25: 297 | L25: 297 | M25: 297 | N25: 297 | O25: =SUM('Expenses 2025'!$C25:$N25) -> 3230.55
B26: Hotel Competence LLC | C26: =217897/507 -> 429.77712 | D26: =217897/507 -> 429.77712 | E26: =217897/507 -> 429.77712 | F26: =217897/507 -> 429.77712 | G26: =217897/507 -> 429.77712 | H26: =217897/507 -> 429.77712 | I26: 525 | J26: =217897/507 -> 429.77712 | K26: =217897/507 -> 429.77712 | L26: =217897/507 -> 429.77712 | M26: =217897/507 -> 429.77712 | N26: 429.78 | O26: =SUM('Expenses 2025'!$C26:$N26) -> 5252.5512
B27: PARQUEO | J27: 500 | K27: 500 | L27: 500 | M27: 250 | N27: 250 | O27: =SUM('Expenses 2025'!$C27:$N27) -> 2000
B28: OSA | D28: 795 | H28: 791 | L28: 791 | N28: 791 | O28: =SUM('Expenses 2025'!$C28:$N28) -> 3168
B29: HACIENDA - RENTA | D29: 11201 | O29: =SUM('Expenses 2025'!$C29:$N29) -> 11201
B30: Limpieza - servecios profossionales | J30: 88 | K30: 131 | L30: 120 | N30: =337+192+117 -> 646 | O30: =SUM('Expenses 2025'!$C30:$N30) -> 985
B31: TOTAL | C31: =SUM(C13:C30) -> 5040.3117 | D31: =SUM(D13:D30) -> 17953.223 | E31: =SUM(E13:E30) -> 4229.1447 | F31: =SUM(F13:F30) -> 5882.2047 | G31: =SUM(G13:G30) -> 6439.5947 | H31: =SUM(H13:H30) -> 5438.4047 | I31: =SUM(I13:I30) -> 5456.0176 | J31: =SUM(J13:J30) -> 6078.5447 | ... N31: =SUM(N13:N30) -> 7162.08 | O31: =SUM(C31:N31) -> 81302.43
B32: Variable operating expenses | C32: JANUARY | D32: FEBRUARY | E32: MARCH | F32: APRIL | G32: MAY | H32: JUNE | I32: JULY | J32: AUGUST | K32: SEPTEMBER | L32: OCTOBER | M32: NOVEMBER | N32: DECEMBER | O32: TOTAL
B33: FLORES | C33: =332581/507 -> 655.9783 | D33: 312 | E33: 520 | F33: 385.82 | G33: 834.35 | I33: 576 | J33: 595 | K33: 180 | N33: =154+120+148+83 -> 505 | O33: =SUM('Expenses 2025'!$C33:$M33) -> 4059.1483
B34: Maxi Pali | C34: =47090/507 -> 92.879684 | D34: 160 | E34: 708.64 | F34: 341.7 | G34: 113.35 | H34: 333.71 | I34: 234 | J34: 200 | O34: =SUM('Expenses 2025'!$C34:$M34) -> 2184.2797
B35: BM | C35: 155 | D35: 80 | E35: 401 | F35: 30 | H35: 112.57 | I35: 180 | J35: 200 | M35: 177 | O35: =SUM('Expenses 2025'!$C35:$M35) -> 1335.57
B36: WALMART | C36: 250 | D36: 566 | J36: 129 | O36: =SUM('Expenses 2025'!$C36:$M36) -> 945
B37: HR Suplidora | C37: 1275.5 | D37: 718 | E37: 483.38 | F37: 1104.51 | O37: =SUM('Expenses 2025'!$C37:$M37) -> 3581.39
B38: Pequeno Mundo | C38: =239000/507 -> 471.40039 | D38: 377.12 | E38: 148 | H38: 11.83 | I38: 145 | J38: 144 | N38: 60 | O38: =SUM('Expenses 2025'!$C38:$M38) -> 1297.3504
B39: BREAKFAST | E39: 1680 | F39: 1697 | J39: 6000 | K39: 250 | L39: 250 | O39: =SUM('Expenses 2025'!$C39:$M39) -> 9877
B40: variance | C40: =850222/507 -> 1676.9665 | D40: 503 | E40: 2500 | F40: 628.64 | G40: 2600 | I40: 1000 | J40: 1018 | K40: 600 | L40: 609 | M40: 600 | N40: =85+114+83+150+85 -> 517 | O40: =SUM('Expenses 2025'!$C40:$M40) -> 11735.606
B41: TOTAL | C41: =SUM(C33,C34,C35,C36,C37,C38,C39,C40) -> 4577.7249 | D41: =SUM(D33,D34,D35,D36,D37,D38,D39,D40) -> 2716.12 | E41: =SUM(E33,E34,E35,E36,E37,E38,E39,E40) -> 6441.02 | F41: =SUM(F33,F34,F35,F36,F37,F38,F39,F40) -> 4187.67 | G41: =SUM(G33,G34,G35,G36,G37,G38,G39,G40) -> 3547.7 | H41: =SUM(H33,H34,H35,H36,H37,H38,H39,H40) -> 458.11 | I41: =SUM(I33,I34,I35,I36,I37,I38,I39,I40) -> 2135 | J41: =SUM(J33,J34,J35,J36,J37,J38,J39,J40) -> 8286 | ... O41: =SUM(O33,O34,O35,O36,O37,O38,O39,O40) -> 35015.345
B42: NELSON | C42: 1070 | D42: 440 | E42: 1035 | F42: 222.88 | G42: 1025.64 | H42: 631.16 | I42: 540 | J42: 3300 | K42: 600 | L42: 1711 | M42: 2200 | N42: 1012 | O42: =SUM(C42:N42) -> 13787.68
B43: AC | G43: 1145 | H43: 150 | I43: 282 | J43: 600 | M43: 1147 | O43: =SUM(C43:N43) -> 3324
B44: NOVEX | C44: =22000.00006/507 -> 43.392505 | G44: 87.38 | J44: 292 | K44: 863 | M44: 201 | O44: =SUM(C44:N44) -> 1486.7725
...

Sheet Income&Expenses 2025
B1: Hotel Yuli Income
B3: 2025
B5: Hotel Info | C5: rooms | D5: 20
C6: January | D6: February | E6: March | F6: April | G6: May | H6: June | I6: July | J6: August | K6: September | L6: October | M6: November | N6: December | O6: Total
B9: TOTAL GROSS PROFIT | C9: =50249.97+3000 -> 53249.97 | D9: =52097.05+3000 -> 55097.05 | E9: =50905.55+3000 -> 53905.55 | F9: =42120.94+3000 -> 45120.94 | G9: =23232.87+3000 -> 26232.87 | H9: =15734.49+3000 -> 18734.49 | I9: =24570.91+3000 -> 27570.91 | J9: =37723.81+3000 -> 40723.81 | K9: 27285.88 | L9: 11264.51 | M9: 31595.01 | N9: 49402.97 | O9: =SUM(C9:N9) -> 440183.96
B10: Total Operating Costs​ | C10: 29783.168 | D10: 39692.993 | E10: 40568.945 | F10: 28814.165 | G10: 28875.065 | H10: 20134.205 | I10: 21608.058 | J10: 39741.895 | K10: 22423.585 | L10: 22405.465 | M10: 34424.055 | N10: 29992 | O10: =SUM(C10:N10) -> 358463.6
B11: TOTAL NET PROFIT | C11: =SUM(C9-C10) -> 23466.802 | D11: =SUM(D9-D10) -> 15404.057 | E11: =SUM(E9-E10) -> 13336.605 | F11: =SUM(F9-F10) -> 16306.775 | G11: =SUM(G9-G10) -> -2642.1947 | H11: =SUM(H9-H10) -> -1399.7147 | I11: =SUM(I9-I10) -> 5962.8524 | J11: =SUM(J9-J10) -> 981.91533 | ... O11: =SUM(O9-O10) -> 81720.364
B14: Occupancy Rate | C14: 0.9 | D14: 0.94 | E14: 0.9 | F14: 0.77 | G14: 0.54 | H14: 0.43 | I14: 0.73 | J14: 0.78 | K14: 0.7 | L14: 0.44 | M14: 0.7 | N14: 75 % | O14: 0.71
B15: ADR – Average Daily Rate | C15: 75.7 | D15: 80,59 $ | E15: 74,68 $ | F15: 74,88 $ | G15: 57,39 $ | H15: 52,30 $ | I15: 58,60 $ | J15: 64,88 $ | K15: 52,90 $ | L15: 60,17 $ | M15: 58.93 | N15: 79.5 | O15: =AVERAGE(C15:N15) -> 71.376667
B16: RevPAR – Revenue per Available Room | C16: 68.24 | D16: 75,80 $ | E16: 67,04 $ | F16: 57,48 $ | G16: 31,01 $ | H16: 22,27 $ | I16: 43,07 $ | J16: 50,58 $ | K16: 37 $ | L16: 26,62 $ | M16: 47.14 | N16: 59.92 | O16: =AVERAGE(C16:N16) -> 58.433333
B17: RevPOR – Revenue per Occupied Room | O17: 87.16
B18: CPOR – Cost per Occupied Room | O18: 69.31
B19: Direct Booking Ratio
B20: OTA Commission Cost %
B21: GOPPAR – Gross Operating Profit per Available Room | O21: 12.67

Sheet Expenses 2026
B1: Hotel Yuli EXPENSES
B2: 2026
C6: January | D6: February | E6: March | F6: April | G6: May | H6: June | I6: July | J6: August | K6: September | L6: October | M6: November | N6: December | O6: Total
B8: EMPLOYEE COSTS | C8: JANUARY | D8: FEBRUARY | E8: MARCH | F8: APRIL | G8: MAY | H8: JUNE | I8: JULY | J8: AUGUST | K8: SEPTEMBER | L8: OCTOBER | M8: NOVEMBER | N8: DECEMBER | O8: TOTAL
B9: PLANILLA | C9: 5200 | D9: 6157 | E9: 6000 | F9: 6186.69 | G9: 6166.11 | H9: 7030 | I9: 7200 | J9: 7150
B10: CCSS | C10: 2131 | D10: 2450 | E10: 2424 | F10: 2636 | G10: 2646 | H10: 2979 | I10: 2979 | J10: 2979
B11: Henrry | C11: 1695 | D11: 1695 | E11: 1695 | F11: 1695 | O11: =SUM('Expenses 2026'!$C11:$N11) -> 6780
B12: TOTAL | C12: =SUM(C9,C10,C11) -> 9026 | D12: =SUM(D9,D10,D11) -> 10302 | E12: =SUM(E9,E10,E11) -> 10119 | F12: =SUM(F9,F10,F11) -> 10517.69 | G12: =SUM(G9,G10,G11) -> 8812.11 | H12: =SUM(H9,H10) -> 10009 | I12: =SUM(I9,I10) -> 10179 | J12: =SUM(J9,J10) -> 10129 | K12: =SUM(K9,K10) -> 0 | L12: =SUM(L9,L10) -> 0 | M12: =SUM(M9,M10,M11) -> 0 | N12: =SUM(N9:N11) -> 0 | O12: =SUM(C12:N12) -> 79093.8
B13: Fixed operating expenses | C13: JANUARY | D13: FEBRUARY | E13: MARCH | F13: APRIL | G13: MAY | H13: JUNE | I13: JULY | J13: AUGUST | K13: SEPTEMBER | L13: OCTOBER | M13: NOVEMBER | N13: DECEMBER | O13: TOTAL
B14: Accountant | C14: =65+165 -> 230 | D14: =170+65 -> 235 | E14: 230 | F14: =178.58+65 -> 243.58 | G14: =178.58+65+404 -> 647.58 | H14: =177+65+178.98+65.89 -> 486.87 | I14: =179.38+65.89 -> 245.27 | J14: 250
B15: MANTENIMIENTO DE PISCINAS | C15: 250 | D15: 248 | E15: 248 | F15: 248 | G15: 248 | H15: 248 | I15: 248 | J15: 248
B16: Gas | C16: =100+82+102+20 -> 304 | D16: 100 | E16: =86+86 -> 172 | F16: =87+100 -> 187 | G16: =22+100 -> 122 | H16: =88+22+89 -> 199 | I16: =112.36+90+20+89.69 -> 312.05 | J16: =110+22 -> 132
B17: Electric | C17: 2810 | D17: 2200 | E17: 2177 | F17: 2177 | G17: 2177 | H17: 2333.55 | I17: 2400 | J17: 2756.64
B18: Water | C18: 518 | D18: 607 | E18: 761 | F18: 761 | G18: 500 | H18: 535 | I18: 680.61 | J18: 682.06 | K18: 681
B19: INTERNET | C19: 90 | D19: 91.92 | E19: 95.59 | F19: 95.59 | G19: 95.59 | H19: 95.59 | I19: 95.59 | J19: 95.59 | K19: 95.59 | L19: 95.59 | M19: 95.59 | N19: 95.59
B20: TELEPHONE | C20: 32 | D20: 33.09 | E20: 33.09 | F20: 33.09 | G20: 33.09 | H20: 33.09 | I20: 33.09 | J20: 33.09 | K20: 33.09 | L20: 33.09 | M20: 33.09 | N20: 33.09 | O20: =SUM('Expenses 2026'!$C20:$N20) -> 395.99
B21: Strauss Water | C21: =14771.75/507 -> 29.135602 | D21: =14771.75/507 -> 29.135602 | E21: =14771.75/507 -> 29.135602 | F21: =14771.75/507 -> 29.135602 | G21: =14771.75/507 -> 29.135602 | H21: =14771.75/507 -> 29.135602 | I21: =14771.75/507 -> 29.135602 | J21: =14771.75/507 -> 29.135602 | ... N21: =14771.75/507 -> 29.135602 | O21: =SUM('Expenses 2026'!$C21:$N21) -> 349.62722
B22: SERVICIOS SANITARIOS JS | C22: 425 | F22: =534.73+226 -> 760.73 | J22: 2333.45
B23: GOOGLE LLC | C23: 56 | D23: 56 | E23: 56 | F23: 56 | G23: 56 | H23: 56 | I23: 56 | J23: 56 | K23: 56 | L23: 56 | M23: 56 | N23: 56 | O23: =SUM('Expenses 2026'!$C23:$N23) -> 672
B24: GOOGLE ADS | C24: 102 | D24: 170 | E24: 283 | F24: 175 | G24: 421 | H24: 445.53 | I24: 253.44 | J24: 238.22
B25: MNK Seguros | C25: 297 | D25: 297.01 | E25: 230.31 | F25: 230.31 | G25: 230.31 | H25: 297 | I25: 297 | J25: 297 | K25: 297 | L25: 297 | M25: 297 | N25: 297 | O25: =SUM('Expenses 2026'!$C25:$N25) -> 3363.94
B26: Hotel Competence LLC | C26: =217897/507 -> 429.77712 | D26: =217897/507 -> 429.77712 | E26: =217897/507 -> 429.77712 | F26: =217897/507 -> 429.77712 | G26: =217897/507 -> 429.77712 | H26: =217897/507 -> 429.77712 | I26: 400 | J26: 400 | K26: 400 | L26: 400 | M26: 400 | N26: 400 | O26: =SUM('Expenses 2026'!$C26:$N26) -> 4978.6627
B27: PARQUEO | C27: 250 | D27: 250 | E27: 250 | F27: 250 | G27: 250 | H27: 250 | I27: 250 | J27: 250 | K27: 250 | L27: 250 | M27: 250 | N27: 250 | O27: =SUM('Expenses 2026'!$C27:$N27) -> 3000
B28: OSA | C28: =377+57+998+62+58 -> 1552 | D28: =62+1866.61 -> 1928.61 | F28: 580 | G28: 250
B29: HACIENDA - RENTA | C29: 450 | D29: 8094.58 | H29: 2650.98
B30: Limpieza - servecios profossionales | C30: =617+95.94 -> 712.94 | D30: 80 | E30: 320 | F30: 180 | G30: 77 | I30: =29.91+72.6 -> 102.51 | K30: 251.99
B31: TOTAL | C31: =SUM(C13:C30) -> 8537.8527 | D31: =SUM(D13:D30) -> 14850.123 | E31: =SUM(E13:E30) -> 5314.9027 | F31: =SUM(F13:F30) -> 6436.2127 | G31: =SUM(G13:G30) -> 5566.4827 | H31: =SUM(H13:H30) -> 8089.5227 | I31: =SUM(I13:I30) -> 5402.6956 | J31: =SUM(J13:J30) -> 7801.1856 | ... N31: =SUM(N13:N30) -> 1160.8156 | O31: =SUM(C31:N31) -> 67575.23
B32: Variable operating expenses | C32: JANUARY | D32: FEBRUARY | E32: MARCH | F32: APRIL | G32: MAY | H32: JUNE | I32: JULY | J32: AUGUST | K32: SEPTEMBER | L32: OCTOBER | M32: NOVEMBER | N32: DECEMBER | O32: TOTAL
B33: SUPPLIES | C33: =187+90+240+193+241+58 -> 1009 | D33: =241.47+150+95+266+293+87.48+204.17 -> 1337.12 | E33: 1548 | F33: =225+126+135+225 -> 711 | H33: =158+136+82+231+196.24+100 -> 903.24 | I33: =97+30+208.07+22+226.29+232.6+245.21 -> 1061.17 | J33: =156.31+0+201+188+176 -> 721.31 | K33: 204.61
B34: HR Suplidora | C34: 1273 | I34: 1497
B35: Breakfast to go | J35: 184 | K35: =74.33+90.3 -> 164.63
B36: Variance Pequeno / WALMART ... | C36: =90+607+151+700+136+91 -> 1775 | D36: =1537 -> 1537 | E36: 2500
B37: TOTAL | C37: =SUM(C33:C36) -> 4057 | D37: =SUM(D33:D36) -> 2874.12 | E37: =SUM(E33:E36) -> 4048 | F37: =SUM(F33:F36) -> 711 | G37: =SUM(G33:G36) -> 0 | H37: =SUM(H33:H36) -> 903.24 | I37: =SUM(I33:I36) -> 2558.17 | J37: =SUM(J33:J36) -> 905.31 | ... O37: =SUM(O33:O36) -> 0
B38: NELSON and others | C38: 421 | D38: =81.38+153.35+185.27 -> 420 | E38: 350 | F38: 50 | G38: 388 | H38: =110+110.55 -> 220.55 | I38: =126.4+300+223.24+47.42+67.57+256+239+94.18 -> 1353.81 | J38: =46.04+210+142.88+158.38+497+110+38+135 -> 1337.3 | K38: =300+0 -> 300
B39: AC | C39: 532 | G39: 1100 | H39: 523 | I39: 685.62 | J39: 89
B40: NOVEX | C40: 823 | E40: 720
B41: Ferretería Palmares | C41: 15 | D41: 360 | F41: 907
B42: Ferreteria EPA S.A. | E42: 535 | F42: 80 | G42: 200
B43: EL COLONO | D43: 1564.68 | E43: 1123 | F43: 100 | G43: 100 | H43: 481.62 | I43: 1047.98 | J43: 1460.46
B44: FERRETERIA IGUANA VERDE | C44: 270 | D44: 875.68 | E44: 228 | F44: =578+505 -> 1083 | G44: 217 | H44: 147.3 | I44: 676.69 | J44: 182
...

Sheet  Income&Expenses 2026
B1: Hotel Yuli Income
B3: 2026
B5: Hotel Info | C5: rooms | D5: 20
C6: January | D6: February | E6: March | F6: April | G6: May | H6: June | I6: July | J6: August | K6: September | L6: October | M6: November | N6: December | O6: Total
B9: TOTAL GROSS PROFIT | C9: =61180+357 -> 61537 | D9: =61224+315 -> 61539 | E9: =59865.9+146 -> 60011.9 | F9: =45134+418 -> 45552 | G9: =31057.36+235 -> 31292.36 | H9: =24109.07+317 -> 24426.07 | I9: =37279.35+1030 -> 38309.35 | J9: =47054.03+844 -> 47898.03
B10: Total Operating Costs​ | C10: 29371.853 | D10: 39303.603 | E10: 35329.153 | F10: 26336.493 | G10: 21462.123 | H10: 24249.373 | I10: 27350.236 | J10: 27413.256
B11: TOTAL NET PROFIT | C11: =SUM(C9-C10) -> 32165.147 | D11: =SUM(D9-D10) -> 22235.397 | E11: =SUM(E9-E10) -> 24682.747 | F11: =SUM(F9-F10) -> 19215.507 | G11: =SUM(G9-G10) -> 9830.2373 | H11: =SUM(H9-H10) -> 176.69728 | I11: =SUM(I9-I10) -> 10959.114 | J11: =SUM(J9-J10) -> 20484.774 | L11: =SUM(L9-L10) -> 0 | M11: =SUM(M9-M10) -> 0 | N11: =SUM(N9-N10) -> 0 | O11: =SUM(O9-O10) -> 0
B14: Occupancy Rate | C14: 89 % | D14: 0.92 | E14: 0.78 | F14: 0.83 | G14: 0.7 | H14: 0.53 | I14: 0.8 | J14: 0.79
B15: ADR – Average Daily Rate | C15: 80,14 $ | D15: 84.46 | E15: 77.21 | F15: 67.7 | G15: 51.46 | H15: 78.3 | I15: 63.51 | J15: 79.08
B16: RevPAR – Revenue per Available Room | C16: 71,55 $ | D16: 77.95 | E16: 60.16 | F16: 56.1 | G16: 36.08 | H16: 41.34 | I16: 50.51 | J16: 62.49
B17: RevPOR – Revenue per Occupied Room
B18: CPOR – Cost per Occupied Room
B19: Direct Booking Ratio
B20: OTA Commission Cost %
B21: GOPPAR – Gross Operating Profit per Available Room
